<?xml version="1.0" ?>
<!-- =================================================================================== -->
<!-- |    This document was autogenerated by xacro from /home/tw017/Desktop/PipetteDetect/catkin_ws/src/mycobot_320_moveit/urdf/mycobot_pro.urdf.xacro | -->
<!-- |    EDITING THIS FILE BY HAND IS NOT RECOMMENDED                                 | -->
<!-- =================================================================================== -->
<robot name="mycobot_pro">
    <link name="world" />
    <joint name="world2base" type="fixed">
        <parent link="world" />
        <child link="base_link" />
    </joint>
    <link name="base_link">
        <visual>
            <geometry>
                <mesh filename="package://mycobot_320_moveit/urdf/320_urdf/base.dae" />
            </geometry>
            <origin rpy=" 0 0 3.1415926" xyz="0 0 0 " />
        </visual>
        <collision>
            <origin rpy=" 0 0 3.1415926" xyz="0 0 0.05 " />
            <geometry>
                <cylinder length="0.100" radius="0.0725" />
            </geometry>
        </collision>
        <inertial>
            <mass value="1.0" />
            <inertia ixx="0.00218" ixy="0.0" ixz="0.0" iyy="0.00218" iyz="0.0" izz="0.00263" />
            <origin xyz="0 0 0" rpy="0 0 0" />
        </inertial>
    </link>
    <link name="link1">
        <visual>
            <geometry>
                <mesh filename="package://mycobot_320_moveit/urdf/320_urdf/link1_1.dae" />
            </geometry>
            <origin rpy=" 0 0 0" xyz="0 0 0 " />
        </visual>
        <collision>
            <origin rpy=" 0 0 0" xyz="0 0 -0.02 " />
            <geometry>
                <cylinder length="0.106" radius="0.043" />
            </geometry>
        </collision>
        <inertial>
            <mass value="0.5" />
            <inertia ixx="0.00070" ixy="0.0" ixz="0.0" iyy="0.00070" iyz="0.0" izz="0.00046" />
            <origin xyz="0 0 0" rpy="0 0 0" />
        </inertial>
    </link>
    <link name="link2">
        <visual>
            <geometry>
                <mesh filename="package://mycobot_320_moveit/urdf/320_urdf/link2.dae" />
            </geometry>
            <origin rpy=" 0 0 3.1415926" xyz="0 0 0.0587 " />
        </visual>
        <collision>
            <origin rpy="0 -1.5708 0" xyz="0.07 0 0.095 " />
            <geometry>
                <cylinder length="0.18" radius="0.036" />
            </geometry>
        </collision>
        <inertial>
            <mass value="0.7" />
            <inertia ixx="0.00212" ixy="0.0" ixz="0.0" iyy="0.00212" iyz="0.0" izz="0.00045" />
            <origin xyz="0 0 0" rpy="0 0 0" />
        </inertial>
    </link>
    <link name="link3">
        <visual>
            <geometry>
                <mesh filename="package://mycobot_320_moveit/urdf/320_urdf/link3.dae" />
            </geometry>
            <origin rpy=" 0 0 3.1415926" xyz="0 0 0.038 " />
        </visual>
        <collision>
            <origin rpy=" 0 -1.5708 0" xyz="0.044 0 0 " />
            <geometry>
                <cylinder length="0.14" radius="0.0305" />
            </geometry>
        </collision>
        <inertial>
            <mass value="0.5" />
            <inertia ixx="0.00093" ixy="0.0" ixz="0.0" iyy="0.00093" iyz="0.0" izz="0.00023" />
            <origin xyz="0 0 0" rpy="0 0 0" />
        </inertial>
    </link>
    <link name="link4">
        <visual>
            <geometry>
                <mesh filename="package://mycobot_320_moveit/urdf/320_urdf/link4.dae" />
            </geometry>
            <origin rpy=" 0 0 0" xyz="0 -0.001 0 " />
        </visual>
        <collision>
            <origin rpy=" 0 -1.5708 1.5708" xyz="0.0 -0.014 0 " />
            <geometry>
                <cylinder length="0.083" radius="0.029" />
            </geometry>
        </collision>
        <inertial>
            <mass value="0.2" />
            <inertia ixx="0.00016" ixy="0.0" ixz="0.0" iyy="0.00016" iyz="0.0" izz="0.00008" />
            <origin xyz="0 0 0" rpy="0 0 0" />
        </inertial>
    </link>
    <link name="link5">
        <visual>
            <geometry>
                <mesh filename="package://mycobot_320_moveit/urdf/320_urdf/link5.dae" />
            </geometry>
            <origin rpy=" 0  0 3.1415926" xyz="0 0.002  0 " />
        </visual>
        <collision>
            <origin rpy=" 1.5708 1.5708 0" xyz="0 -0.01 0 " />
            <geometry>
                <cylinder length="0.0849" radius="0.029" />
            </geometry>
        </collision>
        <inertial>
            <mass value="0.2" />
            <inertia ixx="0.00016" ixy="0.0" ixz="0.0" iyy="0.00016" iyz="0.0" izz="0.00008" />
            <origin xyz="0 0 0" rpy="0 0 0" />
        </inertial>
    </link>
    <link name="link6">
        <visual>
            <geometry>
                <mesh filename="package://mycobot_320_moveit/urdf/320_urdf/link6.dae" />
            </geometry>
            <material name="grey">
                <color rgba="0.5 0.5 0.5 1" />
            </material>
            <origin rpy=" 0 1.5708 0" xyz="-0.502 -0.090 -0.096 " />
        </visual>
        <collision>
            <origin rpy=" 0 0 0" xyz="0.0 0 -0.01 " />
            <geometry>
                <cylinder length="0.0225" radius="0.026" />
            </geometry>
        </collision>
        <inertial>
            <mass value="0.2" />
            <inertia ixx="0.00002" ixy="0.0" ixz="0.0" iyy="0.00002" iyz="0.0" izz="0.00003" />
            <origin xyz="0 0 0" rpy="0 0 0" />
        </inertial>
    </link>
    <joint name="arm_joint_0" type="revolute">
        <axis xyz="0 0 1" />
        <limit effort="100.0" lower="-3.14" upper="3.14159" velocity="5" />
        <parent link="base_link" />
        <child link="link1" />
        <origin rpy="0 0 0" xyz="0 0 0.17846" />
    </joint>
    <joint name="arm_joint_1" type="revolute">
        <axis xyz="0 0 1" />
        <limit effort="100.0" lower="-3.14" upper="3.14159" velocity="5" />
        <parent link="link1" />
        <child link="link2" />
        <origin rpy="0 -1.5708 1.5708" xyz="0 0 0" />
    </joint>
    <joint name="arm_joint_2" type="revolute">
        <axis xyz=" 0 0 1" />
        <limit effort="100.0" lower="-3.14" upper="3.14159" velocity="5" />
        <parent link="link2" />
        <child link="link3" />
        <origin rpy="0 0 0" xyz="0.13635 0 0   " />
    </joint>
    <joint name="arm_joint_3" type="revolute">
        <axis xyz=" 0 0 1" />
        <limit effort="100.0" lower="-3.14" upper="3.14159" velocity="5" />
        <parent link="link3" />
        <child link="link4" />
        <origin rpy=" 0 0 1.57080" xyz="0.1 0 0.09 " />
    </joint>
    <joint name="arm_joint_4" type="revolute">
        <axis xyz="0 0 1" />
        <limit effort="100.0" lower="-3.14" upper="3.14159" velocity="5" />
        <parent link="link4" />
        <child link="link5" />
        <origin rpy="1.5708 -1.5708 0" xyz="0 -0.07318 0" />
    </joint>
    <joint name="arm_joint_5" type="revolute">
        <axis xyz="0 0 1" />
        <limit effort="100.0" lower="-3.14" upper="3.14159" velocity="5" />
        <parent link="link5" />
        <child link="link6" />
        <origin rpy="-1.5708 0 0" xyz="0.00 0.06635 0" />
    </joint>
    <transmission name="arm_tran_0">
        <type>transmission_interface/SimpleTransmission</type>
        <joint name="arm_joint_0">
            <hardwareInterface>hardware_interface/PositionJointInterface</hardwareInterface>
        </joint>
        <actuator name="arm_motor_0">
            <hardwareInterface>PositionJointInterface</hardwareInterface>
            <mechanicalReduction>1</mechanicalReduction>
        </actuator>
    </transmission>
    <transmission name="arm_tran_1">
        <type>transmission_interface/SimpleTransmission</type>
        <joint name="arm_joint_1">
            <hardwareInterface>hardware_interface/PositionJointInterface</hardwareInterface>
        </joint>
        <actuator name="arm_motor_1">
            <hardwareInterface>PositionJointInterface</hardwareInterface>
            <mechanicalReduction>1</mechanicalReduction>
        </actuator>
    </transmission>
    <transmission name="arm_tran_2">
        <type>transmission_interface/SimpleTransmission</type>
        <joint name="arm_joint_2">
            <hardwareInterface>hardware_interface/PositionJointInterface</hardwareInterface>
        </joint>
        <actuator name="arm_motor_2">
            <hardwareInterface>PositionJointInterface</hardwareInterface>
            <mechanicalReduction>1</mechanicalReduction>
        </actuator>
    </transmission>
    <transmission name="arm_tran_3">
        <type>transmission_interface/SimpleTransmission</type>
        <joint name="arm_joint_3">
            <hardwareInterface>hardware_interface/PositionJointInterface</hardwareInterface>
        </joint>
        <actuator name="arm_motor_3">
            <hardwareInterface>PositionJointInterface</hardwareInterface>
            <mechanicalReduction>1</mechanicalReduction>
        </actuator>
    </transmission>
    <transmission name="arm_tran_4">
        <type>transmission_interface/SimpleTransmission</type>
        <joint name="arm_joint_4">
            <hardwareInterface>hardware_interface/PositionJointInterface</hardwareInterface>
        </joint>
        <actuator name="arm_motor_4">
            <hardwareInterface>PositionJointInterface</hardwareInterface>
            <mechanicalReduction>1</mechanicalReduction>
        </actuator>
    </transmission>
    <transmission name="arm_tran_5">
        <type>transmission_interface/SimpleTransmission</type>
        <joint name="arm_joint_5">
            <hardwareInterface>hardware_interface/PositionJointInterface</hardwareInterface>
        </joint>
        <actuator name="arm_motor_5">
            <hardwareInterface>PositionJointInterface</hardwareInterface>
            <mechanicalReduction>1</mechanicalReduction>
        </actuator>
    </transmission>
    <!--ros_control
  plugin-->
    <gazebo>
        <plugin filename="libgazebo_ros_control.so" name="gazebo_ros_control">
            <robotNamespace>/robot_b</robotNamespace>
        </plugin>
    </gazebo>
    <!--joint_state_publisher
  plugin-->
    <gazebo>
        <plugin filename="libgazebo_ros_joint_state_publisher.so" name="joint_state_publisher">
            <jointName>arm_joint_0, arm_joint_1, arm_joint_2, arm_joint_3, arm_joint_4, arm_joint_5</jointName>
        </plugin>
    </gazebo>
</robot>

