<?xml version="1.0"?>
<robot xmlns:xacro="http://www.ros.org/wiki/xacro" name="cobotta">

<xacro:macro name="define_cobotta_arm" params="parent prefix base_xyz base_rpy">
	<!-- <gazebo>
		<plugin name="gazebo_ros_control" filename="libgazebo_ros_control.so">
			<robotNamespace>/cobotta</robotNamespace>
		</plugin>
	</gazebo> -->
	<!-- <link name="world" /> -->
	<joint name="${prefix}_joint_w" type="fixed">
		<parent link="${parent}" />
		<child link="${prefix}_base_link" />
		<origin xyz="${base_xyz}" rpy="${base_rpy}" />
	</joint>
	<link name="${prefix}_base_link">
		<visual>
			<origin rpy="0 0 0" xyz="0 0 0" />
			<geometry>
				<mesh filename="package://denso_robot_descriptions/cobotta_description/base_link.dae" scale="1 1 1" />
			</geometry>
		</visual>
		<collision>
			<origin rpy="0 0 0" xyz="0 0 0" />
			<geometry>
				<mesh filename="package://denso_robot_descriptions/cobotta_description/base_link.dae" scale="1 1 1" />
			</geometry>
		</collision>
		<inertial>
			<mass value="1" />
			<origin rpy="0.000000 0.000000 0.000000" xyz="0.000000 0.000000 0.000000" />
			<inertia ixx="1" ixy="0" ixz="0" iyy="1" iyz="0" izz="1" />
		</inertial>
	</link>
	<link name="${prefix}_J1">
		<visual>
			<origin rpy="0 0 0" xyz="0 0 0" />
			<geometry>
				<mesh filename="package://denso_robot_descriptions/cobotta_description/J1.dae" scale="1 1 1" />
			</geometry>
		</visual>
		<collision>
			<origin rpy="0 0 0" xyz="0 0 0" />
			<geometry>
				<mesh filename="package://denso_robot_descriptions/cobotta_description/J1.dae" scale="1 1 1" />
			</geometry>
		</collision>
		<inertial>
			<mass value="1" />
			<origin rpy="0.000000 0.000000 0.000000" xyz="0.000000 0.000000 0.000000" />
			<inertia ixx="1" ixy="0" ixz="0" iyy="1" iyz="0" izz="1" />
		</inertial>
	</link>
	<joint name="${prefix}_joint_1" type="revolute">
		<parent link="${prefix}_base_link" />
		<child link="${prefix}_J1" />
		<origin rpy="0.000000 0.000000 0.000000" xyz="0.000000 0.000000 0.108000" />
		<axis xyz="-0.000000 -0.000000 1.000000" />
		<limit effort="1" lower="-2.61799387799149" upper="2.61799387799149" velocity="0.383012504350156" />
		<dynamics damping="0" friction="0" />
	</joint>
	<transmission name="${prefix}_trans_1">
		<type>transmission_interface/SimpleTransmission</type>
		<joint name="${prefix}_joint_1">
			<hardwareInterface>hardware_interface/PositionJointInterface</hardwareInterface>
		</joint>
		<actuator name="${prefix}_motor_1">
			<hardwareInterface>hardware_interface/PositionJointInterface</hardwareInterface>
			<mechanicalReduction>1</mechanicalReduction>
		</actuator>
	</transmission>
	<link name="${prefix}_J2">
		<visual>
			<origin rpy="0 0 0" xyz="0 0 0" />
			<geometry>
				<mesh filename="package://denso_robot_descriptions/cobotta_description/J2.dae" scale="1 1 1" />
			</geometry>
		</visual>
		<collision>
			<origin rpy="0 0 0" xyz="0 0 0" />
			<geometry>
				<mesh filename="package://denso_robot_descriptions/cobotta_description/J2.dae" scale="1 1 1" />
			</geometry>
		</collision>
		<inertial>
			<mass value="1" />
			<origin rpy="0.000000 0.000000 0.000000" xyz="0.000000 0.000000 0.000000" />
			<inertia ixx="1" ixy="0" ixz="0" iyy="1" iyz="0" izz="1" />
		</inertial>
	</link>
	<joint name="${prefix}_joint_2" type="revolute">
		<parent link="${prefix}_J1" />
		<child link="${prefix}_J2" />
		<origin rpy="0.000000 0.000000 0.000000" xyz="0.000000 0.000000 0.072000" />
		<axis xyz="-0.000000 1.000000 -0.000000" />
		<limit effort="1" lower="-1.0471975511966" upper="1.74532925199433" velocity="0.37256670877697" />
		<dynamics damping="0" friction="0" />
	</joint>
	<transmission name="${prefix}_trans_2">
		<type>transmission_interface/SimpleTransmission</type>
		<joint name="${prefix}_joint_2">
			<hardwareInterface>hardware_interface/PositionJointInterface</hardwareInterface>
		</joint>
		<actuator name="${prefix}_motor_2">
			<hardwareInterface>hardware_interface/PositionJointInterface</hardwareInterface>
			<mechanicalReduction>1</mechanicalReduction>
		</actuator>
	</transmission>
	<link name="${prefix}_J3">
		<visual>
			<origin rpy="0 0 0" xyz="0 0 0" />
			<geometry>
				<mesh filename="package://denso_robot_descriptions/cobotta_description/J3.dae" scale="1 1 1" />
			</geometry>
		</visual>
		<collision>
			<origin rpy="0 0 0" xyz="0 0 0" />
			<geometry>
				<mesh filename="package://denso_robot_descriptions/cobotta_description/J3.dae" scale="1 1 1" />
			</geometry>
		</collision>
		<inertial>
			<mass value="1" />
			<origin rpy="0.000000 0.000000 0.000000" xyz="0.000000 0.000000 0.000000" />
			<inertia ixx="1" ixy="0" ixz="0" iyy="1" iyz="0" izz="1" />
		</inertial>
	</link>
	<joint name="${prefix}_joint_3" type="revolute">
		<parent link="${prefix}_J2" />
		<child link="${prefix}_J3" />
		<origin rpy="0.000000 0.000000 0.000000" xyz="0.000000 0.000000 0.165000" />
		<axis xyz="-0.000000 1.000000 -0.000000" />
		<limit effort="1" lower="0.314159265358979" upper="2.44346095279206" velocity="0.68942250783028" />
		<dynamics damping="0" friction="0" />
	</joint>
	<transmission name="${prefix}_trans_3">
		<type>transmission_interface/SimpleTransmission</type>
		<joint name="${prefix}_joint_3">
			<hardwareInterface>hardware_interface/PositionJointInterface</hardwareInterface>
		</joint>
		<actuator name="${prefix}_motor_3">
			<hardwareInterface>hardware_interface/PositionJointInterface</hardwareInterface>
			<mechanicalReduction>1</mechanicalReduction>
		</actuator>
	</transmission>
	<link name="${prefix}_J4">
		<visual>
			<origin rpy="0 0 0" xyz="0 0 0" />
			<geometry>
				<mesh filename="package://denso_robot_descriptions/cobotta_description/J4.dae" scale="1 1 1" />
			</geometry>
		</visual>
		<collision>
			<origin rpy="0 0 0" xyz="0 0 0" />
			<geometry>
				<mesh filename="package://denso_robot_descriptions/cobotta_description/J4.dae" scale="1 1 1" />
			</geometry>
		</collision>
		<inertial>
			<mass value="1" />
			<origin rpy="0.000000 0.000000 0.000000" xyz="0.000000 0.000000 0.000000" />
			<inertia ixx="1" ixy="0" ixz="0" iyy="1" iyz="0" izz="1" />
		</inertial>
	</link>
	<joint name="${prefix}_joint_4" type="revolute">
		<parent link="${prefix}_J3" />
		<child link="${prefix}_J4" />
		<origin rpy="0.000000 0.000000 0.000000" xyz="-0.012000 0.020000 0.088000" />
		<axis xyz="-0.000000 -0.000000 1.000000" />
		<limit effort="1" lower="-2.96705972839036" upper="2.96705972839036" velocity="0.702189591308619" />
		<dynamics damping="0" friction="0" />
	</joint>
	<transmission name="${prefix}_trans_4">
		<type>transmission_interface/SimpleTransmission</type>
		<joint name="${prefix}_joint_4">
			<hardwareInterface>hardware_interface/PositionJointInterface</hardwareInterface>
		</joint>
		<actuator name="${prefix}_motor_4">
			<hardwareInterface>hardware_interface/PositionJointInterface</hardwareInterface>
			<mechanicalReduction>1</mechanicalReduction>
		</actuator>
	</transmission>
	<link name="${prefix}_J5">
		<visual>
			<origin rpy="0 0 0" xyz="0 0 0" />
			<geometry>
				<mesh filename="package://denso_robot_descriptions/cobotta_description/J5.dae" scale="1 1 1" />
			</geometry>
		</visual>
		<collision>
			<origin rpy="0 0 0" xyz="0 0 0" />
			<geometry>
				<mesh filename="package://denso_robot_descriptions/cobotta_description/J5.dae" scale="1 1 1" />
			</geometry>
		</collision>
		<inertial>
			<mass value="1" />
			<origin rpy="0.000000 0.000000 0.000000" xyz="0.000000 0.000000 0.000000" />
			<inertia ixx="1" ixy="0" ixz="0" iyy="1" iyz="0" izz="1" />
		</inertial>
	</link>
	<joint name="${prefix}_joint_5" type="revolute">
		<parent link="${prefix}_J4" />
		<child link="${prefix}_J5" />
		<origin rpy="0.000000 0.000000 0.000000" xyz="0.000000 -0.020000 0.089500" />
		<axis xyz="-0.000000 1.000000 -0.000000" />
		<limit effort="1" lower="-1.65806278939461" upper="2.35619449019234" velocity="0.702189591308619" />
		<dynamics damping="0" friction="0" />
	</joint>
	<transmission name="${prefix}_trans_5">
		<type>transmission_interface/SimpleTransmission</type>
		<joint name="${prefix}_joint_5">
			<hardwareInterface>hardware_interface/PositionJointInterface</hardwareInterface>
		</joint>
		<actuator name="${prefix}_motor_5">
			<hardwareInterface>hardware_interface/PositionJointInterface</hardwareInterface>
			<mechanicalReduction>1</mechanicalReduction>
		</actuator>
	</transmission>
	<link name="${prefix}_J6">
		<visual>
			<origin rpy="0 0 0" xyz="0 0 0" />
			<geometry>
				<mesh filename="package://denso_robot_descriptions/cobotta_description/J6.dae" scale="1 1 1" />
			</geometry>
		</visual>
		<collision>
			<origin rpy="0 0 0" xyz="0 0 0" />
			<geometry>
				<mesh filename="package://denso_robot_descriptions/cobotta_description/J6.dae" scale="1 1 1" />
			</geometry>
		</collision>
		<inertial>
			<mass value="1" />
			<origin rpy="0.000000 0.000000 0.000000" xyz="0.000000 0.000000 0.000000" />
			<inertia ixx="1" ixy="0" ixz="0" iyy="1" iyz="0" izz="1" />
		</inertial>
	</link>
	<joint name="${prefix}_joint_6" type="revolute">
		<parent link="${prefix}_J5" />
		<child link="${prefix}_J6" />
		<origin rpy="0.000000 0.000000 0.000000" xyz="0.000000 -0.044500 0.042000" />
		<axis xyz="-0.000000 -0.000000 1.000000" />
		<limit effort="1" lower="-2.96705972839036" upper="2.96705972839036" velocity="1.05386470893922" />
		<dynamics damping="0" friction="0" />
	</joint>
	<transmission name="${prefix}_trans_6">
		<type>transmission_interface/SimpleTransmission</type>
		<joint name="${prefix}_joint_6">H
		
			<hardwareInterface>hardware_interface/PositionJointInterface</hardwareInterface>
		</joint>
		<actuator name="${prefix}_motor_6">
			<hardwareInterface>hardware_interface/PositionJointInterface</hardwareInterface>
			<mechanicalReduction>1</mechanicalReduction>
		</actuator>
	</transmission>
</xacro:macro>
</robot>