<?xml version="1.0"?>
<robot xmlns:xacro="http://ros.org/wiki/xacro" name="k3hand">

  <link name="wrist">
    <visual>
      <geometry>
        <mesh filename="package://mycobot_320_moveit/urdf/k3_urdf/wrist.dae" />
      </geometry>
      <origin xyz="0 0 0" rpy="0 0 0" />
    </visual>
    <collision>
      <geometry>
        <cylinder length="0.06" radius="0.025" />
      </geometry>
      <origin xyz="0 0 -0.015" rpy="-1.570796 0 0" />
    </collision>
    <inertial>
      <mass value="0.1" />
      <inertia ixx="1.0" ixy="0.0" ixz="0.0" iyy="1.0" iyz="0.0" izz="1.0" />
    </inertial>
  </link>
  <link name="thumb_met">
    <visual>
      <geometry>
        <mesh filename="package://mycobot_320_moveit/urdf/k3_urdf/thumb_met.dae" />
      </geometry>
      <origin xyz="0.0 0.0080 0.043" rpy="0 0 0" />
    </visual>
    <collision>
      <geometry>
        <box size="0.0225 0.035 0.012" />
      </geometry>
      <origin xyz="0.0 -0.007 -0.008" rpy="0.88 0 0" />
    </collision>
    <inertial>
      <mass value="0.01" />
      <inertia ixx="1.0" ixy="0.0" ixz="0.0" iyy="1.0" iyz="0.0" izz="1.0" />
    </inertial>
  </link>
  <link name="thumb_middle_1">
    <visual>
      <geometry>
        <mesh filename="package://mycobot_320_moveit/urdf/k3_urdf/thumb_middle_1.dae" />
      </geometry>
      <origin xyz="0.0 0.0225 0.0607" />
    </visual>
    <collision>
      <geometry>
        <box size="0.0225 0.012 0.05" />
      </geometry>
      <origin xyz="0.0 0.0 -0.02" rpy="0 0 0" />
    </collision>
    <inertial>
      <mass value="0.01" />
      <inertia ixx="1.0" ixy="0.0" ixz="0.0" iyy="1.0" iyz="0.0" izz="1.0" />
    </inertial>
  </link>
  <link name="thumb_middle_2">
    <visual>
      <geometry>
        <mesh filename="package://mycobot_320_moveit/urdf/k3_urdf/thumb_middle_2.dae" />
      </geometry>
      <origin xyz="0.0 0.0225 0.0965" />
    </visual>
    <collision>
      <geometry>
        <box size="0.0225 0.012 0.05" />
      </geometry>
      <origin xyz="0.0 0.0 -0.02" rpy="0 0 0" />
    </collision>
    <inertial>
      <mass value="0.01" />
      <inertia ixx="1.0" ixy="0.0" ixz="0.0" iyy="1.0" iyz="0.0" izz="1.0" />
    </inertial>
  </link>


  <link name="thumb_tip">
    <visual>
      <geometry>
        <mesh filename="package://mycobot_320_moveit/urdf/k3_urdf/thumb_tip.dae" />
      </geometry>
      <origin xyz="0.0 0.0225 0.1325" />
    </visual>
    <collision>
      <geometry>
        <box size="0.0225 0.015 0.040" />
      </geometry>
      <origin xyz="0.0 -0.0015 -0.015" rpy="0 0 0" />
    </collision>
    <inertial>
      <mass value="0.01" />
      <inertia ixx="1.0" ixy="0.0" ixz="0.0" iyy="1.0" iyz="0.0" izz="1.0" />
    </inertial>
  </link>

  <link name="fing_met_1">
    <visual>
      <geometry>
        <mesh filename="package://mycobot_320_moveit/urdf/k3_urdf/fing_met_1.dae" />
        <!-- <box size="0.020 0.030 0.012" /> -->
      </geometry>
      <origin xyz="0.0225 0.0225 0.00" rpy="0.0 0.0 0.0" />
    </visual>
    <collision>
      <geometry>
        <box size="0.020 0.012 0.03" />
      </geometry>
      <origin xyz="0.006 -0.0 0.011" />
    </collision>

    <inertial>
      <mass value="0.01" />
      <inertia ixx="1.0" ixy="0.0" ixz="0.0" iyy="1.0" iyz="0.0" izz="1.0" />
    </inertial>
  </link>

  <link name="fing_base_1">
    <visual>
      <geometry>
        <mesh filename="package://mycobot_320_moveit/urdf/k3_urdf/fing_base_1.dae" />
      </geometry>
      <origin xyz="0.015 0.0225 -0.022" />
    </visual>
    <collision>
      <geometry>
        <box size="0.030 0.03 0.05" />
      </geometry>
      <origin xyz="-0.002 0.008 0.01" />
    </collision>
    <inertial>
      <mass value="0.01" />
      <inertia ixx="1.0" ixy="0.0" ixz="0.0" iyy="1.0" iyz="0.0" izz="1.0" />
    </inertial>
  </link>

  <link name="fing_middle_1">
    <visual>
      <geometry>
        <mesh filename="package://mycobot_320_moveit/urdf/k3_urdf/fing_middle_1.dae" />
      </geometry>
      <origin xyz="0.015 0.0225 -0.022" />
    </visual>
    <collision>
      <geometry>
        <box size="0.020 0.03 0.05" />
      </geometry>
      <origin xyz="-0.007 0.008 0.058" />
    </collision>
    <inertial>
      <mass value="0.01" />
      <inertia ixx="1.0" ixy="0.0" ixz="0.0" iyy="1.0" iyz="0.0" izz="1.0" />
    </inertial>
  </link>
  <link name="fing_tip_1">
    <visual>
      <geometry>
        <mesh filename="package://mycobot_320_moveit/urdf/k3_urdf/fing_tip_1.dae" />
      </geometry>
      <origin xyz="0.015 0.0225 -0.022" />
    </visual>
    <collision>
      <geometry>
        <box size="0.020 0.015 0.02" />
      </geometry>
      <origin xyz="-0.007 0.00 0.09" />
    </collision>
    <inertial>
      <mass value="0.01" />
      <inertia ixx="1.0" ixy="0.0" ixz="0.0" iyy="1.0" iyz="0.0" izz="1.0" />
    </inertial>
  </link>

  <link name="fing_met_2">
    <visual>
      <geometry>
        <mesh filename="package://mycobot_320_moveit/urdf/k3_urdf/fing_met_2.dae" />
      </geometry>
      <origin xyz="-0.0225 0.0225 0.00" rpy="0.0 0.0 0.0" />
    </visual>
    <collision>
      <geometry>
        <box size="0.020 0.0120 0.03" />
      </geometry>
      <origin xyz="-0.006 -0.0 0.011" />
    </collision>

    <inertial>
      <mass value="0.01" />
      <inertia ixx="1.0" ixy="0.0" ixz="0.0" iyy="1.0" iyz="0.0" izz="1.0" />
    </inertial>
  </link>
  <link name="fing_base_2">
    <visual>
      <geometry>
        <mesh filename="package://mycobot_320_moveit/urdf/k3_urdf/fing_base_2.dae" />
      </geometry>
      <origin xyz="-0.015 0.0225 -0.022" />
    </visual>
    <collision>
      <geometry>
        <box size="0.030 0.03 0.05" />
      </geometry>
      <origin xyz="0.002 0.008 0.01" />
    </collision>
    <inertial>
      <mass value="0.01" />
      <inertia ixx="1.0" ixy="0.0" ixz="0.0" iyy="1.0" iyz="0.0" izz="1.0" />
    </inertial>
  </link>

  <link name="fing_middle_2">
    <visual>
      <geometry>
        <mesh filename="package://mycobot_320_moveit/urdf/k3_urdf/fing_middle_2.dae" />
      </geometry>
      <origin xyz="-0.015 0.0225 -0.022" />
    </visual>
    <collision>
      <geometry>
        <box size="0.020 0.03 0.05" />
      </geometry>
      <origin xyz="0.007 0.008 0.058" />
    </collision>
    <inertial>
      <mass value="0.01" />
      <inertia ixx="1.0" ixy="0.0" ixz="0.0" iyy="1.0" iyz="0.0" izz="1.0" />
    </inertial>
  </link>
  <link name="fing_tip_2">
    <visual>
      <geometry>
        <mesh filename="package://mycobot_320_moveit/urdf/k3_urdf/fing_tip_2.dae" />
      </geometry>
      <origin xyz="-0.015 0.0225 -0.022" />
    </visual>
    <collision>
      <geometry>
        <box size="0.020 0.015 0.02" />
      </geometry>
      <origin xyz="0.007 0.0 0.09" />
    </collision>
    <inertial>
      <mass value="0.01" />
      <inertia ixx="1.0" ixy="0.0" ixz="0.0" iyy="1.0" iyz="0.0" izz="1.0" />
    </inertial>
  </link>

  <joint name="hand_joint_0" type="revolute">
    <axis xyz="0.0 -1.0 0.0" />
    <parent link="wrist" />
    <child link="fing_met_1" />
    <origin xyz="-0.0225 -0.0225 0.00" rpy="0 -1.570796 0" />
    <limit lower="-1.570796" upper="0.523599" effort="0.0" velocity="1" />
  </joint>
  <joint name="hand_joint_1" type="revolute">
    <axis xyz="1.0 0.0 0" />
    <parent link="fing_met_1" />
    <child link="fing_base_1" />
    <origin xyz="0.0075 -0.0 0.022" rpy="1.570796 0.0 0.0" />
    <limit lower="-1.570796" upper="1.579796" effort="0.0" velocity="1" />
  </joint>
  <joint name="hand_joint_2" type="revolute">
    <axis xyz="0.0 -1.0 0.0" />
    <parent link="wrist" />
    <child link="fing_met_2" />
    <origin xyz="0.0225 -0.0225 0.00" rpy="0.0 1.570796 0" />
    <limit lower="-0.523599" upper="1.570796" effort="0.0" velocity="1" />
  </joint>
  <joint name="hand_joint_3" type="revolute">
    <axis xyz="-1.0 0.0 0" />
    <parent link="fing_met_2" />
    <child link="fing_base_2" />
    <origin xyz="-0.0075 -0.0 0.022" rpy="1.570796 0.0 0.0" />
    <limit lower="-1.570796" upper="1.570796" effort="0.0" velocity="1" />
  </joint>
  <joint name="hand_joint_4" type="revolute">
    <axis xyz="0.0 1 -1.21" />
    <parent link="wrist" />
    <child link="thumb_met" />
    <origin rpy="0 0 0" xyz="0 -0.0080 -0.043" />
    <limit lower="-1.570796" upper="1.570796" effort="30.0" velocity="1.0" />
  </joint>

  <joint name="hand_joint_5" type="revolute">
    <axis xyz="-1 0.0 0.0" />
    <parent link="thumb_met" />
    <child link="thumb_middle_1" />
    <origin rpy="0 0 0" xyz="0 -0.0145 -0.0177" />
    <limit lower="-0.8726646" upper="2.268928" effort="0.0" velocity="1" />
  </joint>
  <joint name="hand_joint_6" type="revolute">
    <axis xyz="-1 0.0 0.0" />
    <parent link="thumb_middle_1" />
    <child link="thumb_middle_2" />
    <origin rpy="0 0 0" xyz="0 0.0 -0.0358" />
    <limit lower="-1.570796" upper="1.570796" effort="0.0" velocity="1" />
  </joint>
  <joint name="hand_joint_7" type="revolute">
    <axis xyz="-1 0.0 0.0" />
    <parent link="thumb_middle_2" />
    <child link="thumb_tip" />
    <origin rpy="0 0 0" xyz="0 0 -0.036" />
    <limit lower="-1.570796" upper="1.570796" effort="0.0" velocity="1" />
  </joint>

  <joint name="fing_fixed_joint_1_1" type="fixed">
    <parent link="fing_base_1" />
    <child link="fing_middle_1" />
    <origin rpy="0 0 0" xyz="0 0 0.0" />
  </joint>
  <joint name="fing_fixed_joint_1_2" type="fixed">
    <parent link="fing_middle_1" />
    <child link="fing_tip_1" />
    <origin rpy="0 0 0" xyz="0 0 0.0" />
  </joint>
  <joint name="fing_fixed_joint_2_1" type="fixed">
    <parent link="fing_base_2" />
    <child link="fing_middle_2" />
    <origin rpy="0 0 0" xyz="0 0 0.0" />
  </joint>
  <joint name="fing_fixed_joint_2_2" type="fixed">
    <parent link="fing_middle_2" />
    <child link="fing_tip_2" />
    <origin rpy="0 0 0" xyz="0 0 0.0" />
  </joint>

</robot>