<?xml version="1.0"?>
<robot  xmlns:xacro="http://www.ros.org/wiki/xacro" name="firefighter" >
	
<xacro:property name="width" value=".2" />


  <link name="base">
    <visual>
      <geometry>
	     <!--- 0.0 0 -0.04  1.5708 3.14159-->
       <mesh filename="package://mycobot_320_moveit/urdf/mycobot_320_m5_2020/base.dae"/>
      </geometry>
    <origin xyz = "0.0 0 0 " rpy = " 0 0 3.1415926"/>
    </visual>
    <collision>
      <geometry>
	     <!--- 0.0 0 -0.04  1.5708 3.14159-->
       <mesh filename="package://mycobot_320_moveit/urdf/mycobot_320_m5_2020/base.dae"/>
        </geometry>
        <origin xyz = "0.0 0 0 " rpy = " 0 0 3.1415926"/>
    </collision>
  </link>

  <link name="link1">
    <visual>
      <geometry>
       <mesh filename="package://mycobot_320_moveit/urdf/mycobot_320_m5_2020/link1.dae"/>
      </geometry>
    <origin xyz = "0 0 0 " rpy = " 0 0 0"/>
    </visual>
    <collision>
     <geometry>
       <mesh filename="package://mycobot_320_moveit/urdf/mycobot_320_m5_2020/link1.dae"/>
      </geometry>
      <origin xyz = "0 0 0 " rpy = " 0 0 0"/>

    </collision>
  </link>


  <link name="link2">
    <visual>
      <geometry>
       <mesh filename="package://mycobot_320_moveit/urdf/mycobot_320_m5_2020/link2.dae"/>
      </geometry>
      <origin xyz = "0 0 0.0587 " rpy = " 0 0 3.1415926"/>
    </visual>
    <collision>
      <geometry>
       <mesh filename="package://mycobot_320_moveit/urdf/mycobot_320_m5_2020/link2.dae"/>
      </geometry>
      <origin xyz = "0 0 0.0587 " rpy = " 0 0 3.1415926"/>
    </collision>
  </link>


  <link name="link3">
    <visual>
      <geometry>
       <!--- 0.0 0 -0.04 -->
       <mesh filename="package://mycobot_320_moveit/urdf/mycobot_320_m5_2020/link3.dae"/>
      </geometry>
    <origin xyz = "0 0 0.038 " rpy = " 0 0 3.1415926"/>
    </visual>
    <collision>
      <geometry>
       <!--- 0.0 0 -0.04 -->
       <mesh filename="package://mycobot_320_moveit/urdf/mycobot_320_m5_2020/link3.dae"/>
      </geometry>
      <origin xyz = "0 0 0.038 " rpy = " 0 0 3.1415926"/>
    </collision>
  </link>



  <link name="link4">
    <visual>
      <geometry>
       <!--- 0.0 0 -0.04 -->
       <mesh filename="package://mycobot_320_moveit/urdf/mycobot_320_m5_2020/link4.dae"/>
      </geometry>
    <origin xyz = "0 -0.001 0 " rpy = " 0 0 0"/>
    </visual>
    <collision>
       <geometry>
       <!--- 0.0 0 -0.04 -->
       <mesh filename="package://mycobot_320_moveit/urdf/mycobot_320_m5_2020/link4.dae"/>
      </geometry>
      <origin xyz = "0 -0.001 0 " rpy = " 0 0 0"/>
    </collision>
  </link>


  <link name="link5">
    <visual>
      <geometry>
       <!--- 0.0 0 -0.04 -->
       <mesh filename="package://mycobot_320_moveit/urdf/mycobot_320_m5_2020/link5.dae"/>
      </geometry>
    <origin xyz = "0 0.002  0 " rpy = " 0  0 3.1415926"/>
    </visual>
    <collision>
      <geometry>
       <!--- 0.0 0 -0.04 -->
       <mesh filename="package://mycobot_320_moveit/urdf/mycobot_320_m5_2020/link5.dae"/>
      </geometry>
    <origin xyz = "0 0.002  0 " rpy = " 0  0 3.1415926"/>
    </collision>
  </link>

  <link name="link6">
    <visual>
      <geometry>
      <!--- 0.0 0 -0.04 -->
       <mesh filename="package://mycobot_320_moveit/urdf/mycobot_320_m5_2020/link6.dae"/>
      </geometry>
    <origin xyz = "-0.502 -0.090 -0.096 " rpy = " 0 1.5708 0"/>
    </visual>
    <collision>
      <geometry>
       <!--- 0.0 0 -0.04 -->
       <mesh filename="package://mycobot_320_moveit/urdf/mycobot_320_m5_2020/link6.dae"/>
      </geometry>
    <origin xyz = "-0.502 -0.090 -0.096 " rpy = " 0 1.5708 0"/>
    </collision>
  </link>



  <joint name="joint2_to_joint1" type="revolute">
    <axis xyz="0 0 1"/>
    <limit effort = "1000.0" lower = "-3.14" upper = "3.14159" velocity = "0"/>
    <parent link="base"/>
    <child link="link1"/>
    <origin xyz= "0 0 0.17846" rpy = "0 0 0"/> 
  </joint>


  <joint name="joint3_to_joint2" type="revolute">
    <axis xyz="0 0 1"/>
    <limit effort = "1000.0" lower = "-3.14" upper = "3.14159" velocity = "0"/>
    <parent link="link1"/>
    <child link="link2"/>
    <origin xyz= "0 0 0" rpy = "0 -1.5708 1.5708"/> 
  </joint>


  <joint name="joint4_to_joint3" type="revolute">
    <axis xyz=" 0 0 1"/>
    <limit effort = "1000.0" lower = "-3.14" upper = "3.14159" velocity = "0"/>
    <parent link="link2"/>
    <child link="link3"/>
    <origin xyz= "0.13635 0 0   " rpy = "0 0 0"/>  
  </joint>

  <joint name="joint5_to_joint4" type="revolute">
    <axis xyz=" 0 0 1"/>
    <limit effort = "1000.0" lower = "-3.14" upper = "3.14159" velocity = "0"/>
    <parent link="link3"/>
    <child link="link4"/>
     <origin xyz = "0.1 0 0.09 " rpy = " 0 0 1.57080"/>
  </joint>

  <joint name="joint6_to_joint5" type="revolute">
    <axis xyz="0 0 1"/>
    <limit effort = "1000.0" lower = "-3.14" upper = "3.14159" velocity = "0"/>
    <parent link="link4"/>
    <child link="link5"/>
     <origin xyz= "0 -0.07318 0" rpy = "1.5708 -1.5708 0"/>
  </joint>

  <joint name="joint6output_to_joint6" type="revolute">
    <axis xyz="0 0 1"/>
    <limit effort = "1000.0" lower = "-3.14" upper = "3.14159" velocity = "0"/>
    <parent link="link5"/>
    <child link="link6"/>
    <origin xyz= "0.00 0.06635 0" rpy = "-1.5708 0 0"/>
  </joint>

  <xacro:macro name="transmission_macro" params="part index joint_name">
    <transmission name="${part}_tran_${index}">
      <type>transmission_interface/SimpleTransmission</type>
      <joint name="${joint_name}">
        <hardwareInterface>hardware_interface/PositionJointInterface</hardwareInterface>
      </joint>
      <actuator name="${part}_motor_${index}">
        <hardwareInterface>PositionJointInterface</hardwareInterface>
        <mechanicalReduction>1</mechanicalReduction>
      </actuator>
    </transmission>
  </xacro:macro>

  <xacro:transmission_macro index="0" part="arm" joint_name="joint2_to_joint1" />
  <xacro:transmission_macro index="1" part="arm" joint_name="joint3_to_joint2" />
  <xacro:transmission_macro index="2" part="arm" joint_name="joint4_to_joint3"/>
  <xacro:transmission_macro index="3" part="arm" joint_name="joint5_to_joint4"/>
  <xacro:transmission_macro index="4" part="arm" joint_name="joint6_to_joint5"/>
  <xacro:transmission_macro index="5" part="arm" joint_name="joint6output_to_joint6"/>

  <!--ros_control
  plugin-->
  <gazebo>
    <plugin name="gazebo_ros_control" filename="libgazebo_ros_control.so" />
  </gazebo>
  <!--joint_state_publisher
  plugin-->
  <gazebo>
    <plugin name="joint_state_publisher" filename="libgazebo_ros_joint_state_publisher.so">
      <jointName>joint2_to_joint1,joint3_to_joint2,joint4_to_joint3,joint5_to_joint4,joint6_to_joint5,joint6output_to_joint6</jointName>
    </plugin>
  </gazebo>


</robot>

