<?xml version="1.0"?>
<robot xmlns:xacro="http://www.ros.org/wiki/xacro" name="myrobot">

    <link name="world" />
    <joint name="world2base" type="fixed">
        <parent link="world" />
        <child link="base_link" />
    </joint>
    <link name="base_link">
        <visual>
            <geometry>
                <mesh filename="package://myrobot/urdf/320_urdf/base.dae" />
            </geometry>
            <origin xyz="0 0 0 " rpy=" 0 0 3.1415926" />
        </visual>
        <collision>
            <origin xyz="0 0 0.05 " rpy=" 0 0 3.1415926" />
            <geometry>
                <cylinder length="0.100" radius="0.0725" />
            </geometry>
        </collision>
        <inertial>
            <mass value="1.0" />
            <inertia ixx="0.00218" iyy="0.00218" izz="0.00263" ixy="0.0" ixz="0.0" iyz="0.0" />

        </inertial>
    </link>
    <link name="link1">
        <visual>
            <geometry>
                <mesh filename="package://myrobot/urdf/320_urdf/link1_1.dae" />
            </geometry>
            <origin xyz="0 0 0 " rpy=" 0 0 0" />
        </visual>
        <collision>
            <origin xyz="0 0 -0.02 " rpy=" 0 0 0" />
            <geometry>
                <cylinder length="0.106" radius="0.043" />
            </geometry>
        </collision>
        <inertial>
            <mass value="0.5" />
            <inertia ixx="0.00070" iyy="0.00070" izz="0.00046" ixy="0.0" ixz="0.0" iyz="0.0" />

        </inertial>
    </link>
    <link name="link2">
        <visual>
            <geometry>
                <mesh filename="package://myrobot/urdf/320_urdf/link2.dae" />
            </geometry>
            <origin xyz="0 0 0.0587 " rpy=" 0 0 3.1415926" />
        </visual>
        <collision>
            <origin xyz="0.07 0 0.095 " rpy="0 -1.5708 0" />
            <geometry>
                <cylinder length="0.18" radius="0.036" />
            </geometry>
        </collision>
        <inertial>
            <mass value="0.7" />
            <inertia ixx="0.00212" iyy="0.00212" izz="0.00045" ixy="0.0" ixz="0.0" iyz="0.0" />
        </inertial>
    </link>
    <link name="link3">
        <visual>
            <geometry>
                <mesh filename="package://myrobot/urdf/320_urdf/link3.dae" />
            </geometry>
            <origin xyz="0 0 0.038 " rpy=" 0 0 3.1415926" />
        </visual>
        <collision>
            <origin xyz="0.044 0 0 " rpy=" 0 -1.5708 0" />
            <geometry>
                <cylinder length="0.14" radius="0.0305" />
            </geometry>
        </collision>
        <inertial>
            <mass value="0.5" />
            <inertia ixx="0.00093" iyy="0.00093" izz="0.00023" ixy="0.0" ixz="0.0" iyz="0.0" />

        </inertial>
    </link>
    <link name="link4">
        <visual>
            <geometry>
                <mesh filename="package://myrobot/urdf/320_urdf/link4.dae" />
            </geometry>
            <origin xyz="0 -0.001 0 " rpy=" 0 0 0" />
        </visual>
        <collision>
            <origin xyz="0.0 -0.014 0 " rpy=" 0 -1.5708 1.5708" />
            <geometry>
                <cylinder length="0.083" radius="0.029" />
            </geometry>
        </collision>
        <inertial>
            <mass value="0.2" />
            <inertia ixx="0.00016" iyy="0.00016" izz="0.00008" ixy="0.0" ixz="0.0" iyz="0.0" />

        </inertial>
    </link>
    <link name="link5">
        <visual>
            <geometry>
                <mesh filename="package://myrobot/urdf/320_urdf/link5.dae" />
            </geometry>
            <origin xyz="0 0.002  0 " rpy=" 0  0 3.1415926" />
        </visual>
        <collision>
            <origin xyz="0 0.0 0 " rpy=" 1.5708 1.5708 0" />
            <geometry>
                <cylinder length="0.0849" radius="0.029" />
            </geometry>
        </collision>
        <inertial>
            <mass value="0.2" />
            <inertia ixx="0.00016" iyy="0.00016" izz="0.00008" ixy="0.0" ixz="0.0" iyz="0.0" />

        </inertial>
    </link>
    <link name="link6">
        <visual>
            <geometry>
                <mesh filename="package://myrobot/urdf/320_urdf/link6.dae" />
            </geometry>
            <material name="grey">
                <color rgba="0.5 0.5 0.5 1" />
            </material>
            <origin xyz="-0.502 -0.090 -0.096 " rpy=" 0 1.5708 0" />
        </visual>
        <collision>
            <origin xyz="0.0 0 -0.01 " rpy=" 0 0 0" />
            <geometry>
                <cylinder length="0.0225" radius="0.029" />
            </geometry>
        </collision>
        <inertial>
            <mass value="0.2" />
            <inertia ixx="0.00002" iyy="0.00002" izz="0.00003" ixy="0.0" ixz="0.0" iyz="0.0" />

        </inertial>
    </link>
    <link name="hand_collision">
        <visual>
            <geometry>
                <cylinder length="0.05" radius="0.035" />
            </geometry>            
            <material name="grey">
                <color rgba="0.5 0.5 0.5 1" />
            </material>
            <origin xyz="-0.0 -0.0 -0.0 " rpy=" 0 0 0" />
        </visual>
        <collision>
            <origin xyz="0.0 0 -0.0 " rpy=" 0 0 0" />
            <geometry>
                <cylinder length="0.05" radius="0.035" />
            </geometry>
        </collision>
        <inertial>
            <mass value="0.2" />
            <inertia ixx="0.00002" iyy="0.00002" izz="0.00003" ixy="0.0" ixz="0.0" iyz="0.0" />
        </inertial>
    </link>
    <joint name="arm_joint_0" type="revolute">
        <axis xyz="0 0 1" />
        <limit effort="100.0" lower="-2.96706" upper="2.96706" velocity="5" />
        <parent link="base_link" />
        <child link="link1" />
        <origin xyz="0 0 0.17846" rpy="0 0 0" />
    </joint>
    <joint name="arm_joint_1" type="revolute">
        <axis xyz="0 0 1" />
        <limit effort="100.0" lower="-2.7925268" upper="2.7925268" velocity="5" />
        <parent link="link1" />
        <child link="link2" />
        <origin xyz="0 0 0" rpy="0 -1.5708 1.5708" />
    </joint>
    <joint name="arm_joint_2" type="revolute">
        <axis xyz=" 0 0 1" />
        <limit effort="100.0" lower="-2.7925268" upper="2.7925268" velocity="5" />
        <parent link="link2" />
        <child link="link3" />
        <origin xyz="0.13635 0 0   " rpy="0 0 0" />
    </joint>
    <joint name="arm_joint_3" type="revolute">
        <axis xyz=" 0 0 1" />
        <limit effort="100.0" lower="-2.7925268" upper="2.7925268" velocity="5" />
        <parent link="link3" />
        <child link="link4" />
        <origin xyz="0.1 0 0.09 " rpy=" 0 0 1.57080" />
    </joint>
    <joint name="arm_joint_4" type="revolute">
        <axis xyz="0 0 1" />
        <limit effort="100.0" lower="-2.96706" upper="2.96706" velocity="5" />
        <parent link="link4" />
        <child link="link5" />
        <origin xyz="0 -0.07318 0" rpy="1.5708 -1.5708 0" />
    </joint>
    <joint name="arm_joint_5" type="revolute">
        <axis xyz="0 0 1" />
        <limit effort="100.0" lower="-3.054326" upper="3.054326" velocity="5" />
        <parent link="link5" />
        <child link="link6" />
        <origin xyz="0.00 0.06635 0" rpy="-1.5708 0 0" />
    </joint>

    <joint name="link6_to_hand" type="fixed">
        <parent link="link6" />
        <child link="hand_collision" />
        <origin xyz="-0.0 -0.00 0.00" rpy="0 0 0" />
    </joint>

    <joint name="link6_to_magsensor" type="fixed">
        <parent link="link6" />
        <child link="magsensor" />
        <origin xyz="-0.0 -0.00 -0.006" rpy="0 0 0" />
    </joint>

    <link name="magsensor">
        <visual>
            <geometry>
                <box size="0.01 0.01 0.002" />
            </geometry>
            <material name="green">
                <color rgba="0 1 0  1" />
            </material>
            <origin xyz="0 0 0 " rpy=" 0 0 0" />
        </visual>
        <collision>
            <origin xyz="0.0 0 0.0 " rpy=" 0 0 0" />
            <geometry>
                <box size="0.01 0.002 0.01" />
            </geometry>
        </collision>
        <inertial>
            <mass value="0.2" />
            <inertia ixx="0.00002" iyy="0.00002" izz="0.00003" ixy="0.0" ixz="0.0" iyz="0.0" />

        </inertial>
    </link>


    <xacro:macro name="transmission_macro" params="part index">
        <transmission name="${part}_tran_${index}">
            <type>transmission_interface/SimpleTransmission</type>
            <joint name="${part}_joint_${index}">
                <hardwareInterface>hardware_interface/PositionJointInterface</hardwareInterface>
            </joint>
            <actuator name="${part}_motor_${index}">
                <hardwareInterface>PositionJointInterface</hardwareInterface>
                <mechanicalReduction>1</mechanicalReduction>
            </actuator>
        </transmission>
    </xacro:macro>

    <xacro:transmission_macro index="0" part="arm" />
    <xacro:transmission_macro index="1" part="arm" />
    <xacro:transmission_macro index="2" part="arm" />
    <xacro:transmission_macro index="3" part="arm" />
    <xacro:transmission_macro index="4" part="arm" />
    <xacro:transmission_macro index="5" part="arm" />
    <!--ros_control
  plugin-->
    <gazebo>
        <plugin name="gazebo_ros_control" filename="libgazebo_ros_control.so" />
    </gazebo>
    <!--joint_state_publisher
  plugin-->
    <gazebo>
        <plugin name="joint_state_publisher" filename="libgazebo_ros_joint_state_publisher.so">
            <jointName>arm_joint_0, arm_joint_1, arm_joint_2, arm_joint_3, arm_joint_4, arm_joint_5 </jointName>
        </plugin>
    </gazebo>
</robot>